Workbook

Sheet Summary
A1: SUMMARY OF PENDING CP APPLICATIONS PER YEAR as of December 2025
A2: YEAR APPLIED | B2: CAR | C2: I | D2: II | E2: III | F2: IVA | G2: IVB | H2: V | I2: VI/VII | J2: IX | K2: X | L2: XI | M2: XII | N2: XIII | O2: TOTAL
A3: 1990 | I3: =COUNTIF('REGION 67'!$C$1:$C$35,1990) -> 0 | O3: =SUM(B3:N3) -> 0
A4: 2000 | I4: =COUNTIF('REGION 67'!$C$1:$C$35,200) -> 0 | O4: =SUM(B4:N4) -> 0
A5: 2001 | I5: =COUNTIF('REGION 67'!$C$1:$C$35,2001) -> 0 | O5: =SUM(B5:N5) -> 0
A6: 2002 | I6: =COUNTIF('REGION 67'!$C$1:$C$35,2002) -> 0 | O6: =SUM(B6:N6) -> 0
A7: 2003 | G7: 1 | I7: =COUNTIF('REGION 67'!$C$1:$C$35,2003) -> 0 | O7: =SUM(B7:N7) -> 1
A8: 2004 | I8: =COUNTIF('REGION 67'!$C$1:$C$35,2004) -> 0 | O8: =SUM(B8:N8) -> 0
A9: 2005 | I9: =COUNTIF('REGION 67'!$C$1:$C$35,2005) -> 0 | O9: =SUM(B9:N9) -> 0
A10: 2006 | I10: =COUNTIF('REGION 67'!$C$1:$C$35,2006) -> 0 | O10: =SUM(B10:N10) -> 0
A11: 2007 | I11: =COUNTIF('REGION 67'!$C$1:$C$35,2007) -> 1 | K11: 1 | L11: 1 | O11: =SUM(B11:N11) -> 3
A12: 2008 | I12: =COUNTIF('REGION 67'!$C$1:$C$35,1990) -> 0 | M12: 2 | O12: =SUM(B12:N12) -> 2
A13: 2009 | I13: =COUNTIF('REGION 67'!$C$1:$C$35,2009) -> 1 | O13: =SUM(B13:N13) -> 1
A14: 2010 | B14: 2 | C14: 3 | I14: =COUNTIF('REGION 67'!$C$1:$C$35,2010) -> 0 | K14: 4 | L14: 1 | M14: 1 | O14: =SUM(B14:N14) -> 11
A15: 2011 | C15: 7 | G15: 3 | I15: =COUNTIF('REGION 67'!$C$1:$C$35,2011) -> 2 | J15: 2 | K15: 3 | L15: 1 | O15: =SUM(B15:N15) -> 18
A16: 2012 | C16: 2 | G16: 5 | I16: =COUNTIF('REGION 67'!$C$1:$C$35,2012) -> 1 | L16: 1 | O16: =SUM(B16:N16) -> 9
A17: 2013 | C17: 1 | G17: 5 | I17: =COUNTIF('REGION 67'!$C$1:$C$35,2013) -> 0 | J17: 1 | M17: 2 | O17: =SUM(B17:N17) -> 9
A18: 2014 | B18: 1 | C18: 3 | G18: 7 | I18: =COUNTIF('REGION 67'!$C$1:$C$35,2014) -> 0 | L18: 2 | O18: =SUM(B18:N18) -> 13
A19: 2015 | B19: 1 | C19: 9 | G19: 15 | I19: =COUNTIF('REGION 67'!$C$1:$C$35,2015) -> 0 | K19: 6 | L19: 1 | O19: =SUM(B19:N19) -> 32
A20: 2016 | B20: 2 | C20: 7 | E20: 2 | G20: 4 | I20: =COUNTIF('REGION 67'!$C$1:$C$35,2016) -> 0 | J20: 1 | K20: 11 | O20: =SUM(B20:N20) -> 27
A21: 2017 | B21: 1 | C21: 6 | G21: 13 | I21: =COUNTIF('REGION 67'!$C$1:$C$35,2017) -> 0 | J21: 5 | K21: 7 | O21: =SUM(B21:N21) -> 32
A22: 2018 | B22: 7 | C22: 8 | E22: 21 | F22: 1 | G22: 20 | I22: =COUNTIF('REGION 67'!$C$1:$C$35,2018) -> 0 | J22: 2 | K22: 9 | L22: 2 | M22: 1 | O22: =SUM(B22:N22) -> 71
A23: 2019 | B23: 3 | C23: 8 | D23: 3 | G23: 52 | I23: =COUNTIF('REGION 67'!$C$1:$C$35,2019) -> 1 | J23: 9 | K23: 1 | L23: 1 | O23: =SUM(B23:N23) -> 78
A24: 2020 | B24: 2 | C24: 7 | D24: 4 | E24: 1 | F24: 2 | G24: 37 | I24: =COUNTIF('REGION 67'!$C$1:$C$35,2020) -> 0 | J24: 5 | M24: =1+2+1 -> 4 | O24: =SUM(B24:N24) -> 62
A25: 2021 | B25: 5 | C25: 1 | D25: 2 | E25: 13 | F25: 7 | G25: 37 | I25: =COUNTIF('REGION 67'!$C$1:$C$35,2021) -> 0 | J25: 68 | L25: 82 | M25: 7 | O25: =SUM(B25:N25) -> 222
A26: 2022 | B26: 6 | C26: 8 | D26: 3 | E26: 6 | F26: 3 | G26: 23 | I26: =COUNTIF('REGION 67'!$C$1:$C$35,2022) -> 3 | J26: 27 | L26: 92 | M26: 15 | O26: =SUM(B26:N26) -> 186
A27: 2023 | B27: 4 | C27: 10 | D27: 5 | E27: 3 | F27: 3 | H27: 3 | I27: =COUNTIF('REGION 67'!$C$1:$C$35,2023) -> 3 | J27: 37 | L27: 322 | M27: 5 | O27: =SUM(B27:N27) -> 395
A28: 2024 | B28: 20 | C28: 1 | D28: 22 | E28: 17 | F28: 3 | H28: 4 | I28: =COUNTIF('REGION 67'!$C$1:$C$35,2024) -> 4 | J28: 28 | K28: 15 | L28: =797+8 -> 805 | M28: 6 | N28: 151 | O28: =SUM(B28:N28) -> 1076
A29: 2025 | B29: 10 | C29: 0 | D29: 2 | E29: 30 | G29: 2 | H29: 1 | I29: =COUNTIF('REGION 67'!$C$1:$C$35,2025) -> 6 | J29: 1 | K29: 15 | L29: 615 | N29: 24 | O29: =SUM(B29:N29) -> 706
A30: TOTAL | B30: =SUM(B4:B29) -> 64 | C30: =SUM(C4:C29) -> 81 | D30: =SUM(D4:D29) -> 41 | E30: =SUM(E4:E29) -> 93 | F30: =SUM(F4:F29) -> 19 | G30: =SUM(G4:G29) -> 224 | H30: =SUM(H4:H29) -> 8 | I30: =SUM(I4:I29) -> 22 | ... N30: =SUM(N4:N29) -> 175 | O30: =SUM(O2:O29) -> 2954

Sheet Summary per project
A1: List of On-going CP Applications AS OF DECEMBER , 2025
A2: REGION | B2: Government Projects | C2: Mining/ Mineral processing project | D2: Energy Project | E2: Forest Management project | F2: EPR | G2: Research project | H2: Road projects | I2: Sand and Gravel | J2: Irrigation project | K2: Livelihood Programs | L2: Eco-Tourism Project | M2: FLGMA | N2: Telecommunication | O2: Carbon Trading | P2: Tree Cutting project | Q2: Plantation/ Pearl project | R2: Water System Project | S2: Others | T2: TOTAL
A3: CAR | B3: 3 | C3: 8 | D3: 23 | E3: 6 | I3: 1 | J3: 4 | L3: 0 | M3: 10 | N3: 9 | T3: =SUM(B3:S3) -> 64
A4: 1 | C4: 16 | D4: 21 | E4: 1 | G4: 6 | H4: 2 | I4: 17 | J4: 11 | N4: 1 | P4: 1 | Q4: 1 | R4: 1 | S4: 3 | T4: =SUM(B4:S4) -> 81
A5: 2 | B5: 7 | D5: 10 | E5: 6 | G5: 1 | H5: 3 | J5: 2 | L5: 5 | N5: 3 | Q5: 1 | R5: 1 | S5: 2 | T5: =SUM(B5:S5) -> 41
A6: 3 | B6: 4 | C6: 15 | D6: 22 | E6: 18 | F6: 1 | G6: 1 | H6: 10 | I6: 29 | P6: 2 | Q6: 1 | R6: 5 | S6: 6 | T6: =SUM(B6:S6) -> 114
A7: 4A | B7: 4 | C7: 1 | D7: 3 | H7: 1 | I7: 1 | L7: 9 | T7: =SUM(B7:S7) -> 19
A8: 4B | B8: 21 | C8: 7 | D8: 25 | E8: 8 | G8: 9 | H8: 22 | I8: 24 | J8: 7 | L8: 8 | M8: 8 | N8: 20 | Q8: 3 | R8: 9 | S8: 53 | T8: =SUM(B8:S8) -> 224
A9: 5 | B9: 1 | C9: 2 | D9: 1 | L9: 2 | M9: 1 | N9: 1 | T9: =SUM(B9:S9) -> 8
A10: 6&7 | B10: 4 | C10: 8 | D10: 4 | E10: 3 | I10: 2 | J10: 1 | T10: =SUM(B10:S10) -> 22
A11: 9 | B11: 21 | C11: 50 | D11: 12 | E11: 11 | F11: 2 | H11: 31 | I11: 38 | J11: 5 | R11: 3 | S11: 13 | T11: =SUM(B11:S11) -> 186
A12: 10 | B12: 6 | C12: 8 | D12: 9 | E12: 5 | H12: 13 | I12: 5 | J12: 2 | L12: 3 | M12: 1 | N12: 1 | Q12: 9 | R12: 5 | S12: 5 | T12: 72
A13: 11 | B13: 285 | C13: 11 | D13: 9 | E13: 28 | F13: 1 | G13: 22 | H13: 219 | I13: 71 | J13: 3 | K13: 2 | L13: 91 | N13: 15 | O13: 2 | P13: 3 | Q13: 3 | R13: 38 | S13: 1123 | T13: =SUM(B13:S13) -> 1926
A14: 12 | B14: 10 | C14: 7 | D14: 2 | F14: 1 | H14: 8 | I14: 4 | L14: 1 | N14: 2 | P14: 1 | R14: 2 | S14: 5 | T14: =SUM(B14:S14) -> 43
A15: 13 | B15: 58 | C15: 25 | D15: 5 | E15: 25 | F15: 5 | H15: 20 | I15: 11 | J15: 5 | R15: 3 | S15: 18 | T15: =SUM(B15:S15) -> 175
A16: TOTAL | B16: =SUM(B3:B15) -> 424 | C16: =SUM(C3:C15) -> 158 | D16: =SUM(D3:D15) -> 146 | E16: =SUM(E3:E15) -> 111 | F16: =SUM(F3:F15) -> 10 | G16: =SUM(G3:G15) -> 39 | H16: =SUM(H3:H15) -> 329 | I16: =SUM(I3:I15) -> 203 | ... S16: =SUM(S3:S15) -> 1228 | T16: =SUM(B16:S16) -> 2975

Sheet CAR
A1: No. | B1: REGION | C1: DATE OF FILING OF CP APPLICATION | D1: NAME OF PROPONENT | E1: NAME OF PROJECT | F1: Project Cost | G1: LOCATION | H1: Type of Project | I1: AFFECTED AD/ICC/IP (for CP with ongoing FPIC) | J1: STATUS OF APPLICATION | K1: STATUS
B3: ABRA | E3: ABRA | I3: ABRA | N3: ABRA
A4: =A3+1 -> 1 | B4: CAR | C4: 2010 | D4: MR. NESTOR ESPEJO | E4: Forest Land Grazing Management Agreement | F4: No data | G4: Mabungtot, Langiden, Abra | H4: FLGMA | J4: For compliance of RO to CEB's comment | K4: FPIC completed
A5: 2 | B5: CAR | C5: 11/26/2019 | D5: National Irrigation Administration (NIA) | E5: Ilocos Norte-Ilocos Sur-Abra Irrigation Project (INISAIP) | F5: No data | G5: Tineg/ Lagayan, Abra | H5: Irrigation Project | I5: Tinggian | J5: Forwarded Legal Advisory No. 309-10-30-25 to PO | K5: FPIC completed
A6: 3 | B6: CAR | C6: 12/14/2022 | D6: Benido L. Balao-as, Sr | E6: Renewal of Forest Land Grazing Management (FLGMA) | F6: No data | G6: Licuan-Baay, Abra | H6: FLGMA | I6: Tinggian | J6: 2nd RRT Report issued | K6: Ongoing FPIC process
A7: 4 | B7: CAR | C7: 2024 | D7: West Sea Mineral Resources | E7: EXPA No. 130 | F7: No data | G7: Tineg Abra | H7: Mining Project | J7: On-going FPIC Process | K7: Ongoing FPIC process
A8: 5 | B8: CAR | C8: 07/13/2023 | D8: Yamang Mineral Corp. | E8: EXPA-000-129-CAR | F8: No data | G8: Abra | H8: Mining Project | J8: Ongoing FPIC Process
A9: 6 | B9: CAR | C9: 01/21/2025 | D9: Ricardo B. Mactal | E9: SIFMA | F9: No data | G9: Penarubia, Abra | H9: SIFMA | J9: Issued memo to PO re FBI Review Report and re personnel recommendation for FPIC Team | K9: FBI completed
A10: =A9+1 -> 7 | B10: CAR | C10: 07/04/2025 | D10: Joseph Q. Abaya | E10: FLGMA | F10: No data | G10: Bulbula, Licuan-Baay, Abra | H10: FLGMA | J10: Notice of Termination issued | K10: Notice of Termination issued
B11: APAYAO | E11: APAYAO | I11: APAYAO | N11: APAYAO
A12: =A10+1 -> 8 | B12: CAR | C12: 2015 | D12: National Irrigation Administration (NIA) | E12: Lower Apayao River Irrigation Project (LARIP) | F12: No data | G12: Pudtol/ Flora, Apayao | H12: Irrigation Project | I12: Isnag | J12: Compliance of FPIC team to ADO Observation/Comment under review by RRT | K12: FPIC completed
A13: =A12+1 -> 9 | B13: CAR | C13: 06/05/2018 | D13: DENR-CAR | E13: Nagan-Maton Wildlife Critical Habitat | F13: No data | G13: Pudtol, Apayao | H13: Government project | I13: Isnag | J13: Compliance of FPIC Team to the RRT Review Report under review | K13: FPIC completed
A14: =A13+1 -> 10 | B14: CAR | C14: 04/17/2019 | D14: Strategic Power Development Corporation (SPDC) | E14: 10 MW Nabuangan Run-off-River Hydropower Project | F14: No data | G14: Conner, Apayao | H14: energy Project | I14: Isnag | J14: Held in abeyance | K14: For continuation of FPIC process
A15: =A14+1 -> 11 | B15: CAR | C15: 08/25/2022 | D15: Olivia Catral, Manuel Canipas (rep. by Roger Canipas), Bulawan Land Owner's Small Scale Mining Association (BLOSSMA rep by Alexander Bisin), Paul Delwasen (rep by Peter Paul Delwasen), Roman Austodillo, Reynaldo Bugnay | E15: Small Scale Mining Contract (SSMC) | F15: No data | G15: Manag, Conner; Butao, Calanasan; Talifugo, Conner; Eva Garden, Calanasan; Apayao | H15: mining project | I15: Isnag | J15: FPIC WO issued for Calanasan AD | K15: For FPIC process
A16: =A15+1 -> 12 | B16: CAR | C16: 01/06/2023 | D16: Lepanto Consolidated Mining Company and Far Southeast Gold Resources, Inc | E16: Renewal of MPSA No. 001-90-CAR | F16: No data | G16: Mankayan, Benguet | H16: mining project | I16: Kankana-ey | J16: On-going FPIC Process | K16: Ongoing FPIC process
A17: =A16+1 -> 13 | B17: CAR | C17: 03/30/2023 | D17: Apayao PLGU | E17: Inscription of Apayao as the 4th united nations educational scientific cultural organization (UNESCO) biosphere reserve of the Phils. | F17: No data | G17: Apayao | H17: Government project | I17: Isnag | J17: 02/19/2024- Received 2 copies of FBI report | K17: FBI completed
A18: =A17+1 -> 14 | B18: CAR | C18: 2024 | D18: National Power Corporation (NAPOCOR) | E18: Kabugao Diesel Power Plant | F18: No data | H18: Energy Project | J18: 02/14/2025- Transmitted Application Review report Transmitted to PO 02/22/2024- Received lacking documents to support application | K18: Ongoing Review of the application
A19: =A18+1 -> 15 | B19: CAR | C19: 2010 | D19: National Irrigation Administration (NIA) | E19: Small Reservior Irrigation Project (SRIP) | F19: No data | G19: Flora, Apayao | H19: Irrigation | J19: Conducted meeting with NIA. Since the project is already completed, it will undergo validation. | K19: FPIC completed
B20: BENGUET | E20: BENGUET | I20: BENGUET | N20: BENGUET
A21: 16 | B21: CAR | C21: 2016 | D21: COHECO Badeo Corporation | E21: 500MW Pump Storage Hydro Power Project | F21: No data | G21: Kibungan, Benguet | H21: Energy Project | I21: Kankana-ey | J21: Endorsed CP Application to CEB | K21: FPIC completed
A22: =A21+1 -> 17 | B22: CAR | C22: 02/23/2018 | D22: Hedcor Inc | E22: 2.4 MW Sal-angan HEPP | F22: No data | G22: Itogon, Benguet | H22: Energy Project | I22: Ibaloy, Kalanguya, Kankana-ey, Iwak | J22: 05/27/2025- Issued reconstituted FPIC Work Order for FPIC team | K22: For FPIC process
A23: =A22+1 -> 18 | B23: CAR | C23: 06/27/2018 | D23: River Flow Ventures and Power Energy Corporation | E23: 2.7MW Camp John Hay Mini-hydro Electric Power Plant | F23: No data | G23: Baguio City | H23: Energy Project | I23: Ibaloy | J23: 06/04/2025- Forwarded LAO Advisory No. 174-05-28-25 to PO for their compliance | K23: FPIC completed
A24: =A23+1 -> 19 | B24: CAR | C24: 07/13/2018 | D24: Hedcor Inc | E24: 4.5MW Bineng3 HEPP | F24: No data | G24: La Trinidad, Benguet | H24: Energy Project | I24: Ibaloy, Kalanguya, Kankana-ey | J24: Deliberated. For issuance of CP. | K24: FPIC completed
A25: =A24+1 -> 20 | B25: CAR | C25: 2018 | D25: AT Dinum Company | E25: Tublay1 HEPP | F25: No data | G25: Tublay, Benguet | H25: Energy Project | I25: Ibaloy, Kalanguya, Kankana-ey | J25: Deliberated. For issuance of CP. | K25: FPIC completed
A26: =A25+1 -> 21 | B26: CAR | C26: 2019 | D26: MCG Aggregates and Crushing Plant | E26: ISAG permit renewal | F26: No data | G26: Tuba, Benguet | H26: Sand and Gravel | I26: Ibaloy, Kalanguya, Kankana-ey | J26: FPIC Report under review | K26: FPIC completed
A27: =A26+1 -> 22 | B27: CAR | C27: 06/30/2020 | D27: Zak Green Energy Inc | E27: 6MW Naguey HEPP | F27: No data | G27: Atok, Benguet | H27: energy Project | I27: Ibaloy, Kankana-ey | J27: For termination | K27: For termination
A28: =A27+1 -> 23 | B28: CAR | C28: 09/06/2021 | D28: Converge ICT Solutions Inc & MetroWorks ICT Construction Inc | E28: Erection of Converge ICT Solutions Inc Poles and Aerial Installation of Fiber Optic Cable | F28: No data | G28: Tublay, Benguet | H28: Telecommunication Project | I28: Ibaloy, Kalanguya, Kankana-ey | J28: 02/15/2024- Received 2 copies of FBI for evaluation | K28: FBI completed
A29: 24 | B29: CAR | C29: 2021 | D29: SN Aboitiz Power, Inc. | E29: 105MW Ambuklao HEPP | F29: No data on record | G29: Bokod, Benguet | H29: energy project | I29: Ibaloy, Karao | J29: Resolution of non-consent was issued by the ICCs *Received Terminal Report- for review
A30: =A29+1 -> 25 | B30: CAR | C30: 2021 | D30: SN Aboitiz Power, Inc. | E30: 140MW Binga Hydro Electric PP - Upper Agno HEP | F30: No data on record | G30: Itogon, Benguet | H30: energy project | I30: Ibaloy, Kalanguya, Kankana-ey, Iwak | J30: FPIC Book transmitted to ADO per ADO Memo to review (parallel review) For guidance of ADO on issues raised by Bokod. | K30: FPIC completed
A31: =A30+1 -> 26 | B31: CAR | C31: 02/10/2022 | D31: Benguet Corporation | E31: Special Mines Permit covering Slide Fr and East Fr | F31: No data | G31: Itogon, Benguet | H31: Mining project | I31: Ibaloy, Kalanguya, Kankana-ey, Iwak | J31: 03/11/2024-Transmitted issued FPIC WO to PO | K31: For FPIC process
A32: =A31+1 -> 27 | B32: CAR | C32: 2024 | D32: HEDCOR INC. (HCI) Formerly Hedcor Cordillera | E32: 52 MW Kabayan 2 HEPP | F32: No data | G32: Kabayan Benguet | H32: Energy Project | J32: IPO issued Manifestation of No Consent | K32: Ongoing FPIC process
A33: 28 | B33: CAR | C33: 2024 | D33: National Grid Corporation of the Philippines (NGCP) | E33: Ordinary Repeater Relay station | F33: No data | G33: Cabuyao, Mt. Sto. Thomas Poblacion, Tuba Benguet | H33: Telecommunication project | J33: FPIC Validation report under review
A34: =A33+1 -> 29 | B34: CAR | C34: 2024 | D34: Tagel Corp | E34: 20 MW kabayan 4 Hydro electric power Project ( with issued HSC No. 2024-01-953) | F34: No data | G34: Acop, caponga, Tublay Benguet | H34: Energy Project | J34: 01/10/2025- Transmitted to ADO the Comment/Briefer re: Compliance of the FPIC Team and RRT relative to ADO Memorandum Order No. ADO RMD-2024-12-273 (Protest/Opposition to the issuance of CP Tagel Corp.) ***
A35: =A34+1 -> 30 | B35: CAR | C35: 2024 | D35: Phil-Tower Consortium, Inc | E35: Construction of Cellsite Tower | F35: No data | G35: Ucab, Itogon Pico, La Trinidad Benguet | H35: Telecommunication project | J35: Issued Show Cause to Proponent due to failure to conduct FBI activities | K35: In active CP application
A36: =A35+1 -> 31 | B36: CAR | C36: 2024 | D36: San Roque Hydropower, Inc. | E36: 800 MW Lower East Pumped Storage 800 MW West Pumped Storage | F36: No data | G36: Ampucao, Itogon, Benguet | H36: Energy Project | I36: Itogon AD | J36: FPIC-WFP forwarded to Chair for concurrence
A37: 32 | B37: CAR | C37: 2025 | D37: San Roque Hydropower, Inc. | E37: 600 MW Upper East Pumped Storage | F37: No data | G37: Dalupirip, Itogon, Benguet | H37: Energy Project | I37: Itogon AD | J37: FPIC-WFP forwarded to Chair for concurrence
A38: =A37+1 -> 33 | B38: CAR | C38: 2025 | D38: ISRI | E38: Renewal of MPSA No. 152-2000-CAR by ISRI | F38: No data | G38: Mankayan, Benguet | H38: Mining Project | J38: Sent letter to proponent acknowledging the receipt of submitted reports and informing them the constraints of the application for renewal | K38: Ongoing CP application
A39: =A38+1 -> 34 | B39: CAR | C39: 2021 | D39: Benguet Corporation | E39: Exploration Permit Application No. 122 | F39: No data | G39: Virac, Itogon | H39: Mining | J39: For submission of progress report | K39: In active CP application
A40: =A39+1 -> 35 | B40: CAR | C40: 2024 | D40: National Grid Corporation of the Philippines (NGCP) | E40: La Trinidad-Calot 69 KV Transmission Line | F40: No data | G40: Benguet | H40: Energy Project | J40: 01/03/2025- Received request for postponement of scheduled MOA negotiations from proponent due to unresolved issues with the ICCs/IPs and landowners affected | K40: Ongoing FPIC process
A41: =A40+1 -> 36 | B41: CAR | C41: 06/30/2025 | D41: Radio Network Phils., Inc. | E41: FLAG for Telecommunication Facility | F41: No data | G41: Sto. Tomas, Tuba, Benguet | H41: FLAG | I41: Tuba AD | J41: FBI Work Order issued | K41: For FPIC process
...

Sheet REGION 1
A1: t | B1: REGION | C1: DATE OF FILING OF CP APPLICATION | D1: NAME OF PROPONENT | E1: NAME OF PROJECT | F1: Project Cost | G1: LOCATION | H1: Type of Project | I1: AFFECTED AD/ICC/IP (for CP with ongoing FPIC) | J1: STATUS OF APPLICATION | K1: STATUS
A3: 1 | B3: 1 | C3: 2010 | D3: Mina Fortuna | E3: EXPA | H3: Mining Project | J3: due to inaction of the proponent | K3: In active CP application
A4: =+A3+1 -> 2 | B4: 1 | C4: 2010 | D4: Benguet Corp. | E4: FTAA | G4: Adams, Ilocos Norte | H4: Mining Project | J4: ICCs/ Ips issued Resolution of Non-Consent | K4: Ongoing FPIC process
A5: =+A4+1 -> 3 | B5: 1 | C5: 2010 | D5: Benguet Corp.- Cabittauran & Sto Nino Nueva Era | E5: FTAA | G5: Cabittauran & Sto Niño, Nueva Era IN | H5: Mining Project | J5: Issued WO/Memo to Proceed with the FPIC | K5: Ongoing FPIC process
A6: =+A5+1 -> 4 | B6: 1 | C6: 2011 | D6: Malibato Mining Co. Inc. | E6: FYPA-016-1, | G6: Lamag & Patiacan, Quirino, IS | H6: Mining Project | I6: Kankanaey | J6: Stop Operation/No permit issued | K6: In active CP application
A7: =+A6+1 -> 5 | B7: 1 | C7: 2011 | D7: Phil. Great minerals Corp. | E7: Expa 068, | G7: Vintar IN | H7: Mining Project | I7: Imalawa | J7: Stp[ Operation/Finish Contract | K7: In active CP application
A8: =+A7+1 -> 6 | B8: 1 | C8: 2011 | D8: Benguet Corp- Dasar, Isic-Isic, Vintar | E8: FTAA den. ATTA# 003 | G8: Dasar, Isic-isic, Vintar, Ilocos Norte | H8: Mining Project | I8: Imalawa | J8: Issued WO/Memo to Proceed with the FPIC | K8: Ongoing FPIC process
A9: =+A8+1 -> 7 | B9: 1 | C9: 2011 | D9: Benguet Corp- Manalpac & Maan-anteng, Solosona | E9: FTAA den. ATTA# 003 | G9: Manalpac & Maan-anteng, Solsona, Ilocos Norte | H9: Mining Project | I9: Isnag | J9: Issued WO/Memo to Proceed with the FPIC | K9: Ongoing FPIC process
A10: =+A9+1 -> 8 | B10: 1 | C10: 2011 | D10: Primasiera Minerals Inc. ( Reynaldo Guillermo) | E10: FTAA | G10: Cacafean, Marcos, Ilocos Norte | H10: Mining Project | I10: Isnag | J10: no response from ADO after compliance of the recommendations & Findings | K10: In active CP application
A11: =+A10+1 -> 9 | B11: 1 | C11: 2011 | D11: NL UPC Asia | E11: Wind Farm | G11: Ilocos Norte | H11: Energy Project | J11: for en banc deliberation | K11: FPIC completed
A12: =+A11+1 -> 10 | B12: 1 | C12: 2011 | D12: Skymark Mining & Min. Corp.- Monitoring | E12: SLRP & RRW | G12: Sto. Niño, Nueva Era, Ilocos Norte | H12: Mining Project | I12: Tingguian | J12: no response from ADO after compliance of the recommendations & Findings | K12: In active CP application
A13: =+A12+1 -> 11 | B13: 1 | C13: 2012 | D13: Rizal Silica Corp. | E13: Expa 37 | G13: Nueva Era, Ilocos Norte | H13: Mining Project | I13: Tingguian | J13: no response from ADO after compliance of the recommendations & Findings | K13: In active CP application
A14: =+A13+1 -> 12 | B14: 1 | C14: 2012 | D14: Skymark Mining & Min. Corp.- Monitoring | E14: SLUP & Small Scale Mining | G14: Cabittauran, Nueva Era, Ilocos Norte | H14: Mining Project | I14: Tingguian | J14: no response from ADO after compliance of the recommendations & Findings | K14: In active CP application
A15: =+A14+1 -> 13 | B15: 1 | C15: 2013 | D15: South Ocean Mining Corp. | E15: AMPP | G15: Quirino, Ilocos Sur | H15: Mining Project | I15: Kankanaey | J15: no response from ADO after compliance of the recommendations & Findings | K15: In active CP application
A16: =+A15+1 -> 14 | B16: 1 | C16: 2014 | D16: Cordillera Exploration Co. Inc CEXci | E16: Expa 116 | G16: Cervantes, Ilocos Sur | H16: Mining Project | I16: Kankanaey | J16: Issued notice to proceed with the FPIC | K16: Ongoing FPIC process
A17: =+A16+1 -> 15 | B17: 1 | C17: 2014 | D17: North Luzon Renewable Energy | E17: Flag App Windfarm & Transmission Line Right of way located IN | G17: Bangui, Burgos, Ilocos Norte | H17: Energy Project | J17: Waiting submission of the report | K17: FPIC completed
A18: =+A17+1 -> 16 | B18: 1 | C18: 2014 | D18: Lilian Cruz | E18: ISAGPA 317 | G18: Bued, River, Esperanza, Sison, Pangasinan | H18: Sand and Gravel | I18: Ibaloi, Bago & Kankanaey | J18: ISAG application was converted to CSAG and as per last information from the field office a permit was already issued by the Provincial Government of Pangasinan despite the absence of a CP. NCIP coordinated with DENR regarding this issue, and the PENRO undertook to prepare a letter to the Provincial Mining and Regulatory Board Pangasinan requiring them to undergo FPIC prior to the renewal of their permits. This is in compliance with the agreement contained in the Joint Operational Agreement executed by the NCIP R1 and DENR R1 to address contentious issues in the implementation of their respective mandates. The issued permit by the Province of Pangasinan no longer required the CP, hence proponent no longer pursued its issuance with the NCIP. Despite this, proponents are still complying with the provisions of the MOA. | K18: In active CP application
A19: =+A18+1 -> 17 | B19: 1 | C19: 2014 | D19: Jaen Rose Payba & Blessilda Jarasa | E19: ISAGPA# 318 & 319 located | G19: Esperanza, Sison Pangasinan | H19: Sand and Gravel | I19: Ibaloi, Bago & Kankanaey | J19: ISAG application was converted to CSAG and as per last information from the field office a permit was already issued by the Provincial Government of Pangasinan despite the absence of a CP. NCIP coordinated with DENR regarding this issue, and the PENRO undertook to prepare a letter to the Provincial Mining and Regulatory Board Pangasinan requiring them to undergo FPIC prior to the renewal of their permits. This is in compliance with the agreement contained in the Joint Operational Agreement executed by the NCIP R1 and DENR R1 to address contentious issues in the implementation of their respective mandates. The issued permit by the Province of Pangasinan no longer required the CP, hence proponent no longer pursued its issuance with the NCIP. Despite this, proponents are still complying with the provisions of the MOA. | K19: In active CP application
A20: =+A19+1 -> 18 | B20: 1 | C20: 2015 | D20: SAN HAI Aggregates | E20: ISAGPA# 329 & 330 | G20: Esperanza, Sison Pangasinan | H20: Sand and Gravel | I20: Ibaloi, Bago & Kankanaey | J20: Proponent has not complied yet with the submission of documents (Board Resolution and Posting of Bond) as required by Legal Opinion No. 49-07-06-18. | K20: In active CP application
A21: =+A20+1 -> 19 | B21: 1 | C21: 2015 | D21: Darwin Angeles | E21: ISAGPA #329 | G21: Esperanza Sison Pangasinan | H21: Sand and Gravel | I21: Ibaloi, Bago & Kankanaey | J21: ISAG application was converted to CSAG and as per last information from the field office a permit was already issued by the Provincial Government of Pangasinan despite the absence of a CP. NCIP coordinated with DENR regarding this issue, and the PENRO undertook to prepare a letter to the Provincial Mining and Regulatory Board Pangasinan requiring them to undergo FPIC prior to the renewal of their permits. This is in compliance with the agreement contained in the Joint Operational Agreement executed by the NCIP R1 and DENR R1 to address contentious issues in the implementation of their respective mandates. The issued permit by the Province of Pangasinan no longer required the CP, hence proponent no longer pursued its issuance with the NCIP. Despite this, proponents are still complying with the provisions of the MOA. | K21: In active CP application
A22: =+A21+1 -> 20 | B22: 1 | C22: 2015 | D22: SAN HAI Aggregates | E22: Crushing Plant | G22: Cauringan Sison Pangasinan | H22: Sand and Gravel | I22: Ibaloi, Bago & Kankanaey | J22: Proponent has not complied yet with the submission of documents (Board Resolution and Posting of Bond) as required by Legal Opinion No. 49-07-06-18. | K22: In active CP application
A23: =+A22+1 -> 21 | B23: 1 | C23: 2015 | D23: Marita Pascual | E23: ISAGPA no 316 | G23: Cauringan Sison Pangasinan | H23: Sand and Gravel | I23: Ibaloi, Bago & Kankanaey | J23: ISAG application was converted to CSAG and as per last information from the field office a permit was already issued by the Provincial Government of Pangasinan despite the absence of a CP. NCIP coordinated with DENR regarding this issue, and the PENRO undertook to prepare a letter to the Provincial Mining and Regulatory Board Pangasinan requiring them to undergo FPIC prior to the renewal of their permits. This is in compliance with the agreement contained in the Joint Operational Agreement executed by the NCIP R1 and DENR R1 to address contentious issues in the implementation of their respective mandates. The issued permit by the Province of Pangasinan no longer required the CP, hence proponent no longer pursued its issuance with the NCIP. Despite this, proponents are still complying with the provisions of the MOA. | K23: In active CP application
A24: =+A23+1 -> 22 | B24: 1 | C24: 2015 | D24: Blessilda Jarasa | E24: ISAGPA no 318 | G24: Cauringan Sison Pangasinan | H24: Sand and Gravel | I24: Ibaloi, Bago & Kankanaey | J24: Proponent failed to comply as to the comments stated in the Legal Opinion. Proponent has stopped operating since 2017 | K24: In active CP application
A25: =+A24+1 -> 23 | B25: 1 | C25: 2015 | D25: Mathew Liis | E25: ISAGPA | G25: Dungon Sison Pangasinan | H25: Sand and Gravel | I25: Ibaloi, Bago & Kankanaey | J25: Proponent abandoned his application | K25: In active CP application
A26: =+A25+1 -> 24 | B26: 1 | C26: 2015 | D26: Mathew Liis | E26: ISAGPA | G26: Dungon, Sison, Pangasinan | H26: Sand and Gravel | I26: Ibaloi, Bago & Kankanaey | J26: proponent abandoned his application | K26: In active CP application
A27: =+A26+1 -> 25 | B27: 1 | C27: 2015 | D27: Aboitiz Power Corp. | E27: F7.5 MW Cervantes Mankayan-Bakun Hydroelectric Power Project (CMB-HEPP) | G27: Cervantes Mankayan-Bakun | H27: Energy Project | I27: Kankanaey | J27: proponent abandoned their application | K27: In active CP application
A28: 26 | B28: 1 | C28: 2015 | D28: NLREC | E28: Transmission line right of way & windmill | G28: located at Caunayan, Saguigui, Saliksik, Dampig, Mun. Pagudpud & Sitio Masamuyao Payac Bangui Ilocos Norte | H28: Energy Project | I28: Yapayao | J28: waiting for submission of FPIC report | K28: FPIC completed
A29: =+A28+1 -> 27 | B29: 1 | C29: 2016 | D29: Piddig Municipality-Ilocos Norte | E29: FLAg-Piddig Arabica Coffee Plantation | G29: Sitio Lammin, Piddig, Ilocos Norte | H29: Plantation Project | I29: Yapayao | J29: Proponent abandoned their application | K29: In active CP application
A30: 28 | B30: 1 | C30: 2016 | D30: Energy Development Corporation | E30: FFlag Application for Wind Power Project | G30: Caunayan & Balaoi, Pagudpud, Ilocos Norte | H30: Energy Project | I30: Yapayao | J30: Waiting submission of FPIC Report | K30: FPIC completed
A31: =+A30+1 -> 29 | B31: 1 | C31: 2016 | D31: STA CLARA POWER CORPORATION | E31: Hydroelectric Power Plant Project | G31: San Emilio, Ilocos Sur | H31: Energy Project | I31: Itneg & Bago | J31: Recommended for the conduct of FPICProponent abandoned their application | K31: In active CP application
A32: =+A31+1 -> 30 | B32: 1 | C32: 2016 | D32: PHILNEWRIVER POWER CORP | E32: Hydroelectric Power Plant Project | G32: Quirino, Ilocos Sur | H32: Energy Project | I32: Kankanaey | J32: Recommended for the conduct of FPICProponent abandoned their application | K32: In active CP application
A33: =+A32+1 -> 31 | B33: 1 | C33: 2016 | D33: PHILNEWRIVER POWER CORP | E33: Hydroelectric Power Plant Project | G33: Sugpon, Ilocos Sur | H33: Energy Project | I33: Bago & Kankanaey | J33: Recommended for the conduct of FPICProponent abandoned their application | K33: In active CP application
A34: =+A33+1 -> 32 | B34: 1 | C34: 2016 | D34: PHILNEWRIVER POWER CORP | E34: Hydroelectric Power Plant Project | G34: Alilem, Ilocos Sur | H34: Energy Project | I34: Bago & Kankanaey | J34: Recommended for the conduct of FPICProponent abandoned their application | K34: In active CP application
A35: =+A34+1 -> 33 | B35: 1 | C35: 2016 | D35: FOUNDATION FOR THE PHIL ENVIRONMENT | E35: Validation of RSEA-KPNP l | G35: Adams, Ilocos Norte | H35: Others | I35: Isnag & Yapayao | J35: Recommended for the conduct of FPICProponent abandoned their application | K35: In active CP application
A36: =+A35+1 -> 34 | B36: 1 | C36: 2017 | D36: PRYZE GASES, INC. | E36: Special Land Use Permit (SLUP) | G36: Palina, Pigo, La Union | H36: Others | I36: Ibaloi, Bago & Kankanaey | J36: proponent abandoned their application | K36: In active CP application
A37: =+A36+1 -> 35 | B37: 1 | C37: 2017 | D37: Sta. Clara Power Corporation | E37: Hydro-Electric Power Project | G37: Matibuey, San Emilio, Ilocos Sur | H37: Energy Project | I37: Itneg & Bago | J37: proponent abandoned their application | K37: In active CP application
A38: 36 | B38: 1 | C38: 2017 | D38: E.H. Sison Engineers, Co. | E38: GACO Small Reservoir Irrigation Project | G38: Cacadiran, Cabugao, Ilocos Sur | H38: Irrigation Project | I38: Tingguian | J38: on-going FPIC | K38: Ongoing FPIC process
A39: 37 | B39: 1 | C39: 2017 | D39: Anthony Fernand Sunga (Solid Rock Aggregates) | E39: ISAGPA | G39: Agat, Sison, Pangasinan | H39: Sand and Gravel | I39: Ibaloi, Bago & Kankanaey | J39: recommended for the conduct of FPIC | K39: For FPIC process
A40: =+A39+1 -> 38 | B40: 1 | C40: 2017 | D40: NIA C/o E.H. Sison Engineers, CO. | E40: GACO Small Reservoir Irrigation Project | G40: Brgy., Cacadiran & Nagsincaoan, Cabugao Ilocos Sur | H40: Irrigation Project | I40: Tingguian | J40: on-going FPIC | K40: Ongoing FPIC process
A41: =+A40+1 -> 39 | B41: 1 | C41: 2017 | D41: Philnew River Power Corporation | E41: Hydro-electric Power Plant | G41: Brgy. Danac, Sugpon, Ilocos Sur | H41: Energy Project | I41: Bago & Kankanaey | J41: proponent abandoned their application | K41: In active CP application
...

Sheet REGION 2
A1: NO | B1: REGION | C1: DATE OF FILING OF CP APPLICATION | D1: NAME OF PROPONENT | E1: NAME OF PROJECT | F1: Project Cost | G1: LOCATION | H1: Type of Project | I1: AFFECTED AD/ICC/IP (for CP with ongoing FPIC) | J1: STATUS OF APPLICATION | K1: STATUS
A3: 1 | B3: II | C3: 43543 | D3: Felicisimo Seatriz Jr. | E3: FLAGT located in Nangaramoan Environmental Protectors Association San Vicente, Sta. Ana, Cagayan | G3: Sta. Ana, Cagayan | H3: Eco-Tourism | I3: Agta | J3: On-going FPIC process | K3: Ongoing FPIC process
A4: =A3+1 -> 2 | B4: II | C4: 43752 | D4: Sharif Madmo H. Hasim | E4: NELEX sub project feasibility study | G4: Dupax, Sta Fe and Aritao, Nueva Vizcaya | H4: Research | J4: For completion of compliance re: ADO and LAO comments | K4: FPIC completed
A5: =A4+1 -> 3 | B5: II | C5: 43558 | D5: Juan Eugenio L. Roxas | E5: Application for CP FDC Renewables Corp. for the proposed 26 MW Pampang Hydropower project | G5: Kayapa and Sta. Fe, Nueva Vizcaya | H5: Energy | I5: Kalanguya, Iwak, Ibaloi; Kalanguya-Ikalahan | J5: FPIC report and MOA submitted to CO | K5: FPIC completed
A6: =A5+1 -> 4 | B6: II | C6: 44008 | D6: NIA Region 2 | E6: Ilaguen Multipurpose Irrigation and Power Project (IMIPP), San Mariano, Isabela | G6: San Mariano, Isabela | H6: Energy | I6: Agta | J6: On-going FPIC process; conflict resolution with IPC | K6: Ongoing FPIC process
A7: =A6+1 -> 5 | B7: II | C7: 44180 | D7: RBG Electronics | E7: Installation of 20ft Antenna Pole for Internet Connectivity in Ganao, Dupax Del Sur | G7: Dupax del Sur, Nueva Vizcaya | H7: Telecommunication | I7: Bugkalot | J7: On-going FPIC | K7: Ongoing FPIC process
A8: =A7+1 -> 6 | B8: II | C8: 44188 | D8: AT Dinum Energy Inc. | E8: 2.5 Canili HPP | G8: Alfonso Castaneda, Nueva Vizcaya | H8: Energy | I8: Bugkalot | J8: Suspended FPIC process; conflict resolution of concerned ICCs/IPs | K8: Ongoing FPIC process
A9: =A8+1 -> 7 | B9: II | C9: 44008 | D9: Raymundo B. Apil, CESE | E9: Palanan Irrigation Project (PIP) in the Municipality of Palanan | G9: Palanan, Isabela | H9: Irrigation Project | I9: Agta | J9: On-going FPIC | K9: Ongoing FPIC process
A10: =A9+1 -> 8 | B10: II | C10: 44258 | D10: Philippines Air Force | E10: Radar System | G10: Sta. Ana, Cagayan | I10: Agta | J10: For signing of MOA | K10: Ongoing FPIC process
A11: =A10+1 -> 9 | B11: II | C11: 44511 | D11: Mega Philippines, Inc. | E11: Northern Cagayan Geothermal Power Project (GSC No. 2019-02-061) | G11: Lal-lo, Gattaran, Baggao, Penablanca, Cagayan | H11: Energy | I11: Agta | J11: On-going FPIC process | K11: Ongoing FPIC process
A12: =A11+1 -> 10 | B12: II | C12: 44894 | D12: Balibago Waterworks System, Inc. | E12: 1500 CMD Rated Capacity-Water Treatment Plant and Supply System | G12: Banagan, Poblacion and Darapidap, Aritao | H12: Water System | J12: On-going FPIC process | K12: Ongoing FPIC process
A13: =A12+1 -> 11 | B13: II | C13: 44777 | D13: Suzette Padilla | E13: FLAGT | G13: San Vicente, Sta. Ana | H13: Eco-Tourism | I13: Agta | J13: On-going FPIC process | K13: Ongoing FPIC process
A14: =A13+1 -> 12 | B14: II | C14: 44803 | D14: San Jose San Mariano Livelihood Assoc. Inc. | E14: Enhanced NGP | G14: Sitio Diwagden, San Jose, San Mariano, Isabela | H14: Plantation | I14: Agta | J14: On-going FPIC process | K14: Ongoing FPIC process
A15: =A14+1 -> 13 | B15: II | C15: 45086 | D15: DPWH Region II | E15: Road Widening/Off-Carriageway Improvement along NV-Pangasinan Road | G15: Sta. Fe, Nueva Vizcaya | H15: Road Project | J15: On-going FPIC process | K15: Ongoing FPIC process
A16: =A15+1 -> 14 | B16: II | C16: 45054 | D16: NGCP | E16: Ambuklao-Bayombong 230 kV | G16: Bambang and Kayapa | H16: Energy | I16: Kalanguya, Iwak, Ibaloi | J16: On-going FBV | K16: Ongoing Validation Process
A17: =A16+1 -> 15 | B17: II | C17: 45148 | D17: DPWH 2 | E17: Construction of ProposedSan Mariano-Palanan Road | G17: San Mariano and Palanan | H17: Road Project | I17: Agta | J17: On-going FPIC process | K17: Ongoing Validation Process
A18: =A17+1 -> 16 | B18: II | C18: 44952 | D18: DSWD FO2 | E18: KALAHI CIDSS | G18: Babuyan Claro, Calayan | H18: Government Project | I18: Ibatan | J18: On-going FBV process | K18: Ongoing Validation Process
A19: =A18+1 -> 17 | B19: II | C19: 45020 | D19: NGCP | E19: Northern Luzon 230Kv Loop Project | G19: Sta. Praxedes, Claveria, Sanchez Mira, Pamplona, Abulug, Ballesteros, Allacapan and Lal-lo, Cagayan | H19: Energy | I19: Agta, Ibanag, Yapayao | J19: On-going FBV process | K19: Ongoing Validation Process
A20: =A19+1 -> 18 | B20: II | C20: 45534 | D20: Edgepoint Towers Inc | E20: Construction of Cell Tower | G20: Basco, Batanes | H20: Telecommunication | I20: Ivatan | J20: On-going FPIC process | K20: Ongoing Validation Process
A21: =A20+1 -> 19 | B21: II | C21: 45608 | D21: CSU-Carig | E21: Batanes Smart Tourism: Structural Strength of Smart Engineered Greenhouse Across Varying Wind Loads in the Island of Batanes project | G21: Uyugan, Batanes | H21: Eco-Tourism | I21: Ivatan | J21: On-going FBV process | K21: Ongoing Validation Process
A22: =A21+1 -> 20 | B22: II | C22: 45616 | D22: LGU Itbayat | E22: Construction of Logistics Hub | G22: Itbayat, Batanes | H22: Government Project | I22: Ivatan | J22: On-going FBV process | K22: Ongoing Validation Process
A23: =A22+1 -> 21 | B23: II | C23: 45649 | D23: Ludgoron Mining Corporation | E23: EPA (EPA000180II) | G23: Babuyan Claro, Calayan | H23: Energy | I23: Ibatan | J23: On going FBI | K23: Ongoing FBI
A24: =A23+1 -> 22 | B24: II | C24: 45649 | D24: JDVC Resources Corp. | E24: Application for Financial Technical Assistance | G24: Buguey, Cagayan | H24: Energy | I24: n/a | J24: On going FBI | K24: Ongoing FBI
A25: =A24+1 -> 23 | B25: II | C25: 45614 | D25: RIDAI | E25: CBFMA | G25: Rizal, San Guillermo | H25: Forest Management Project | I25: Agta | J25: On going FBI | K25: Ongoing FBI
A26: =A25+1 -> 24 | B26: II | C26: 45630 | D26: BKS Green Energy Corporation | E26: Transmission Line of Limbauan SPP | G26: Cabagan and San Pablo, Isabela | H26: Energy | I26: n/a | J26: On going FBI | K26: Ongoing FBI
A27: =A26+1 -> 25 | B27: II | C27: 45523 | D27: LGU Dupax del Sur | E27: Slaughter House | G27: Palabotan, Dupax del Sur | H27: Government Project | I27: Bugkalot | J27: On going FBV | K27: Ongoing Validation Process
... A43: =A42+1 -> 41 | B43: II | C43: 45677 | D43: OGPI | E43: Various Infra projects | G43: Bambang, Dupax del Norte and del Sur, Bayombong, Bagabag, Diadi and Solano | H43: Infrastructure | I43: Isinai | J43: On going FBV | K43: Ongoing Validation Process

Sheet REGION 3
A1: NO | B1: REGION | C1: DATE OF FILING OF CP APPLICATION | D1: NAME OF PROPONENT | E1: NAME OF PROJECT | F1: PROJECT COST | G1: LOCATION | H1: Type of Project | I1: AFFECTED AD/ICC/IP (for CP with ongoing FPIC) | J1: STATUS OF APPLICATION | K1: STATUS
A3: 1 | B3: III | C3: 2016 | D3: National Grid Corporation of the Philippines (NGCP) | E3: San Jose -Angat 115KV Transmission Line Upgrading Project (SJATLUP) | G3: Norzagaray, Bulacan | H3: Energy Project | J3: Issued RMD-ADO-37-2019-8 dated August 6, 2019 forwarding Legal Opinion 31-08-02-19; no compliance submitted. | K3: FPIC Completed | L3: =COUNTIF(K1:K178, "FPIC completed") -> 7
A4: 2 | B4: III | C4: 2016 | D4: OCEAN BUSINESS CORPORATION & THE MELECIAS | E4: Community Solicited Project for Fruit Tree Plantation Project | G4: Entablado, Brgy. Aglao, San Marcelino, Zambales | H4: Plantation Project | J4: Waiting for compliance to legal opinion no.22-03-12 | K4: FPIC Completed
A5: 3 | B5: III | C5: 2018 | D5: IP Community of Sitio Monicayo, Brgy. Calumpang, City of Mabalacat Pampanga | E5: Community Solicited Projects (Potable Water Supply) | G5: Sitio Monicayo, Brgy. Calumpang, City of Mabalacat Pampanga | H5: Water System | J5: Waiting for Legal Opinion | K5: FPIC Completed
A6: 4 | B6: III | C6: 2018 | D6: Blue Rock Aggregates Corp. | E6: Mabalacat, Pampanga | G6: Sitio Lukutang Malaki, San Isidro, Rodriguez, Rizal | H6: Sand and Gravel | J6: Awaiting compliance of RIV-A; Amend map to exclude R3 area; Waiting for the submission from the project proponent. | K6: In active CP application | L6: =COUNTIF(K1:K178, "In active CP Application") -> 4
A7: 5 | B7: III | C7: 2018 | D7: Mr. Dexter Ivan Lee | E7: Quarry Permit (AQP-B-851-21) | G7: Brgy Banaban Angat Bulacan | H7: Sand and Gravel | J7: MOA Negotiation | K7: Ongoing FPIC process | L7: =COUNTIF(K1:K178, "Ongoing FPIC Process") -> 10
A8: 6 | B8: III | C8: 2018 | D8: Mr. Bobby Millera | E8: Commercial Sand and Gravel Permit | G8: Brgy Maamot San Jose Tarlac | H8: Sand and Gravel | J8: ongoing lateral review of MOA | K8: Ongoing FPIC process
A9: 7 | B9: III | C9: 2018 | D9: Ms. Ruzen Mae Sarah Pasual | E9: Commercial Sand and Gravel Permit | G9: Brgy Maamot San Jose Tarlac | H9: Sand and Gravel | J9: on going madatory activity | K9: Ongoing FPIC process
A10: 8 | B10: III | C10: 2018 | D10: Ms. Sheryl Montaño | E10: Commercial Sand and Gravel Permit | G10: Brgy Maamot San Jose Tarlac | H10: Sand and Gravel | J10: on going madatory activity | K10: Ongoing FPIC process
A11: 9 | B11: III | C11: 2018 | D11: Mr. Michael Santos | E11: Commercial Sand and Gravel Permit | G11: Brgy Maamot San Jose Tarlac | H11: Sand and Gravel | J11: on going madatory activity | K11: Ongoing FPIC process
A12: 10 | B12: III | C12: 2018 | D12: Local Goverment Unit of Bagac, Bataan in Coordination with National Housing Authority (NHA) | E12: Housing Assistance Program for the Indigenous Peoples (HAPIP) of NHA | G12: Sitio Matalangao, Brgy Banawang, and Sitio Duhat Brgy Saysain, Bagac, Bataan | H12: Government Project | J12: - Validation report reviewed - all pertinent documents already transmitted to NHA as per their requirements - MOAs are for Review of NHA | K12: FPIC Completed
A13: 11 | B13: III | C13: 2018 | D13: Local Goverment Unit of Dinalupihan , Bataan in Coordination with National Housing Authority (NHA) | E13: Housing Assistance Program for the Indigenous Peoples (HAPIP) of NHA | G13: Bgry Tubo Tubo, Dinalupihan, Bataan | H13: Government Project | J13: -Validation report reviewed - all pertinent documents transmitted to NHA as per their requirements - MOAs are for Review of NHA | K13: FPIC Completed
A14: 12 | B14: III | C14: 2018 | D14: STKG Trading | E14: Industrial Sand and Gravel Permit Denominated as IPA000319 III | G14: Brgy Lawy Capas Tarlac | H14: Sand and Gravel | J14: For Conduct of Pre FBI conference | K14: Ongoing FPIC process
A15: 13 | B15: III | C15: 2018 | D15: DEPARTMENT OF PUBLIC WORKS AND HIGHWAYS (DPWH) | E15: Improvement/ Contruction of Culat- Cozo- San Ildefonzo road with Bridge. | G15: Brgy. Culat, Cozo and San ildefonzo, Casiguran Aurora. | H15: Road Project | J15: Follow up to field office | K15: In active CP application
A16: 14 | B16: III | C16: 2018 | D16: DEPARTMENT OF PUBLIC WORKS AND HIGHWAYS (DPWH) | E16: Rehabilitation and Improvement of the Dibut Farm to Market Road | G16: Brgy. Dibut San Luis, Aurora | H16: Road Project | J16: for review | K16: In active CP application
A17: 15 | B17: III | C17: 2018 | D17: Luvy Duenas | E17: Industrial Sand and Gravel Permit Denominated as IPA000340 III | G17: Brgy ODonnel Capas Tarlac | H17: Sand and Gravel | J17: FBI Conducted | K17: For FPIC process | L17: =COUNTIF(K1:K178, "For FPIC process") -> 16
A18: 16 | B18: III | C18: 2018 | D18: Ms. Shela Mae Lape Boromeo | E18: Industrial Sand and Gravel Permit Denominated as IPA000271 III | G18: Brgy Iba San Jose Tarlac | H18: Sand and Gravel | J18: FBI Conducted | K18: For FPIC process
A19: 17 | B19: III | C19: 2018 | D19: Zstone enterprises Inc. | E19: Industrial Sand and Gravel Permit Denominated as IPA000272 III | G19: Brgy Iba San Jose Tarlac | H19: Sand and Gravel | J19: FBI Conducted | K19: For FPIC process
A20: 18 | B20: III | C20: 2018 | D20: Mr. Joseph M. Domacena | E20: Industrial Sand and gravel Permit denominated as IPA000396 | G20: Brgy San Juan, Botolan, Zambales | H20: Sand and Gravel | J20: FBI Conducted | K20: For FPIC process
A21: 19 | B21: III | C21: 2018 | D21: Ms. Marilyn F. Dial | E21: Industrial Sand and gravel Permit denominated as IPA000394 | G21: Brgy San Juan, Botolan, Zambales | H21: Sand and Gravel | J21: FBI Conducted | K21: For FPIC process
A22: 20 | B22: III | C22: 2018 | D22: Mr. Edison T. Dagan | E22: Industrial Sand and gravel Permit denominated as IPA000395 | G22: Brgy San Juan, Botolan, Zambales | H22: Sand and Gravel | J22: FBI Conducted | K22: For FPIC process
A23: 21 | B23: III | C23: 2018 | D23: Mr. Jeremay B. Aguilar | E23: Industrial Sand and gravel Permit denominated as IPA000393 | G23: Brgy San Juan, Botolan, Zambales | H23: Sand and Gravel | J23: FBI Conducted | K23: For FPIC process
A24: 22 | B24: III | C24: 2018 | D24: Premium resource and Exploration | E24: Industrial Sand and Gravel Permit IPA000224 III | G24: Brgy. Carael, Botolan, Zambales | H24: Sand and Gravel | J24: FBI Conducted | K24: For FPIC process
A25: 23 | B25: III | C25: 2018 | D25: Mega Boulder Exploration and Resource | E25: Industrial Sand and Gravel Permit IPA000222 III | G25: Brgy. Carael, Botolan, Zambales | H25: Sand and Gravel | J25: FBI Conducted | K25: For FPIC process
A26: 24 | B26: III | C26: 2020 | D26: Ore Asia Mining and Development Corporation | E26: Mineral Production Sharing Agreement Denominated as APSA000410 III | G26: Brgy Camachin DRT, Bulacan | H26: Mining Project | J26: For Conduct of FBI with approved WFP | K26: For FBI | L26: =COUNTIF(K1:K178, "For FBI") -> 13
A27: 25 | B27: III | C27: 2021 | D27: Gruppo International Mining Co., Inc. | E27: Exploration Permit denominated as EXPA000229 | G27: Brgy. Calabgan Casiguran, Aurora | H27: Mining Project | J27: For Conduct of Pre FBI conference | K27: Ongoing FBI | L27: 9
A28: 26 | B28: III | C28: 2021 | D28: Verion Global Mining, Inc. | E28: Exploration Permit Denominated as EXPA 000222 III | G28: Brgy Kalawakan, DRT, Bulacan | H28: Mining Project | J28: For Conduct of Pre FBI conference | K28: Ongoing FBI
A29: 27 | B29: III | C29: 2021 | D29: One Thousand Years Corporation | E29: Exploration Permit Denominated as EXPA 000228 III | G29: Brgys Casalat, Bayabas, and Bukol, DRT, Bulacan | H29: Mining Project | J29: For Conduct of Pre FBI conference | K29: Ongoing FBI
A30: 28 | B30: III | C30: 2021 | D30: Abraham Benson Terry Wong | E30: Industrial Sand and Gravel Permit Denominated as IPA000210 III | G30: Brgy. Manuali Porac Pampanga | H30: Sand and Gravel | J30: for compliance of FBI team | K30: For FPIC process
A31: 29 | B31: III | C31: 2021 | D31: Topmines Quarry Resources | E31: Industrial Sand and Gravel Permit Denominated as IPA00209 III | G31: Brgy Manuali, Porac, Pampanga | H31: Sand and Gravel | J31: for compliance of FBI team | K31: For FPIC process
A32: 30 | B32: III | C32: 2021 | D32: Ian Benson Terry Wong | E32: Industrial Sand and Gravel Permit Denominated as IPA000211 III | G32: Brgy Manuali, Porac, Pampanga | H32: Sand and Gravel | J32: for compliance of FBI team | K32: For FPIC process
A33: 31 | B33: III | C33: 2021 | D33: Metropolitan Waterworks and sewerage system (MWSS) | E33: Angat Water Transmission Improvement Project (AWTIP) – Tunnel 5 | G33: Brgy San Lorenzo, San Mateo and Bigte Norzagaray, Bulacan | H33: Energy Project | J33: FPIC report submitted to ADO | K33: FPIC Completed
A34: 32 | B34: III | C34: 2021 | D34: DEPARTMENT OF PUBLIC WORKS AND HIGHWAYS (DPWH) | E34: Bareto by pass project | G34: Continuation of Naugsol – Tipo – Dinalupihan By- Pass Road | H34: Road Project | J34: For conduct of FBI | K34: For FBI
A35: 33 | B35: III | C35: 2021 | D35: DEPARTMENT OF PUBLIC WORKS AND HIGHWAYS (DPWH) | E35: Construction of Bypass Road Freeport Area of Bataan (FAB) to Bagac – Mariveles Road, Mariveles Bataan | G35: Bagac – Mariveles Road, Mariveles Bataan | H35: Road Project | J35: For Conduct of Pre FBI conference | K35: For FBI
A36: 34 | B36: III | C36: 2021 | D36: DPWH Nueva Ecija 1st District Engineering Office | E36: Construction of Road | G36: Brgy Capintalan Carranglan Nueva Ecija | H36: Road Project | J36: For Conduct of Pre FBI conference | K36: For FBI
A37: 35 | B37: III | C37: 2021 | D37: DEPARTMENT OF PUBLIC WORKS AND HIGHWAYS (DPWH) | E37: Road Construction Project of Department of Public Works and Highways (DPWH) | G37: Brgy Paltic to Brgy Dikapanikian, Dingalan, Aurora | H37: Road Project | J37: for review of compliance | K37: Validation completed | L37: =COUNTIF(K1:K178, "Validation completed") -> 4
A38: 36 | B38: III | C38: 2021 | D38: DEPARTMENT OF PUBLIC WORKS AND HIGHWAYS (DPWH) | E38: Rehabilitation of Water system project | G38: So. Dipontian, Brgy. Cozo, Casiguran Aurora | H38: Water System | J38: for review of compliance | K38: Validation completed
A39: 37 | B39: III | C39: 2021 | D39: Dinalupihan Water District | E39: New Water Source System | G39: Brgy Payangan, Dinalupihan, Bataan | H39: Water System | J39: for review of compliance | K39: Validation completed
A40: 38 | B40: III | C40: 2022 | D40: Oriental Petroleum and Mineral Corporation | E40: Exploration Permit EXPA000231 III, EXPA000240 III | G40: Candelaria, Cabangan, Botolan, Sta Cruz, San Antonio, Masinloc Zambales | H40: Mining Project | J40: for review of compliance | K40: Validation completed
A41: 39 | B41: III | C41: 2022 | D41: NATIONAL GRID CORPORATION OF THE PHILIPPINES (NGCP) | E41: CASTELLEJOS 230 KV SUBSTATION PROJECT | G41: CASTILLEJOS, Zambales | H41: Energy Project | J41: for compliance of FBI team | K41: For FPIC process
...

Sheet REGION 4A
A1: NO | B1: REGION | C1: DATE OF FILING OF CP APPLICATION | D1: NAME OF PROPONENT | E1: NAME OF PROJECT | F1: PROJECT COST | G1: LOCATION | H1: Type of Project | I1: AFFECTED AD/ICC/IP (for CP with ongoing FPIC) | J1: STATUS OF APPLICATION | K1: Status
A3: 1 | B3: IVA | C3: 2018 | D3: Mrs. Teresita Santiago | E3: Agro-Forestry Farm with Eco-Tourism Project (Evening Wind) | G3: Rizal | H3: Eco-tourism | I3: Dumagat/Remontado | J3: For submission of FPIC Report | K3: Ongoing review by RRT | L3: =COUNTIF(K1:K74, "FPIC completed") -> 2
A4: 2 | B4: IVA | C4: 2020 | D4: Malvar Cousins Corporation | E4: Mt. Purro Nature Reserve project | G4: Rizal | H4: Eco-Tourism | I4: Dumagat/Remontado | J4: Reconstituted FPIC Team to resume FPIC Process; Ongoing conduct of FPIC Process | K4: FPIC activities ongoing | L4: =COUNTIF(K1:K74, "FPIC activities ongoing") -> 2
A5: 3 | B5: IVA | C5: 2020 | D5: Real Wind Energy Inc. | E5: Real Wind Energy Power Project-WESC No. 2019-09-133 | G5: Rizal | H5: Energy | I5: Dumagat/Remontado | J5: Assigned WESC to Giga Ace 6; Done conducting MOA negotiation; For issuance of Work Order reconstituting FPIC Team | K5: WESC assigned to Giga Ace 6, Inc.
A6: 4 | B6: IVA | C6: 2021 | D6: Reynaldo Fresno | E6: Agro-Forestry and Eco Tourist Camp Site Project | G6: Rizal | H6: Eco-Tourism | I6: Dumagat/Remontado | J6: Issued FPIC Work Order dated May 6, 2024 | K6: FPIC activities ongoing
A7: 5 | B7: IVA | C7: 2021 | D7: Mr. William Jaime Astrande | E7: The Peak Campsite | G7: Rizal | H7: Eco-Tourism | I7: Dumagat/Remontado | J7: For compliance of FPIC Team to the LAO and ADO findings | K7: Ongoing review by ADO
A8: 6 | B8: IVA | C8: 2021 | D8: Hernando Mandilag Jr | E8: The Apiary Mountain Camp and Farm | G8: Rizal | H8: Eco-Tourism | I8: Dumagat/Remontado | J8: For payment of FBI Fee by the proponent | K8: For FBI | L8: =COUNTIF(K1:K74, "For FBI") -> 3
A9: 7 | B9: IVA | C9: 2021 | D9: Real Wind Energy, Inc. | E9: 250 MW Real Wind Power Project WESC No. 2021-03-153 Phase 3 | G9: Quezon | H9: Energy | I9: Dumagat | J9: Assigned WESC to Giga Ace 6; Done conducting MOA negotiation; For issuance of Work Order reconstituting FPIC Team | K9: WESC assigned to Giga Ace 6, Inc.
A10: 8 | B10: IVA | C10: 2021 | D10: Ridges and Clouds | E10: SAPA | G10: Rizal | H10: Eco-Tourism | I10: Dumagat/Remontado | J10: For conduct of FBI | K10: For FBI
A11: 9 | B11: IVA | C11: 2021 | D11: Grace S. Bagnes | E11: Kamp Maysawa | G11: Rizal | H11: Eco-Tourism | I11: Dumagat/Remontado | J11: For conduct of FBI | K11: For FBI
A12: 10 | B12: IVA | C12: 2021 | D12: Engr. Ramon Lopez-Lazaro | E12: Rainbow 89 Ecopark Camping and Trekking | G12: Rizal | H12: Eco-Tourism | I12: Dumagat/Remontado | J12: For issuance of FPIC Work Order | K12: For FPIC | L12: =COUNTIF(K1:K74, "For FPIC") -> 1
A13: 11 | B13: IVA | C13: 44578 | D13: DPWH IV-A | E13: Construction of Gen. Nakar-Dingalan Road, Gen. Nakar Quezon | G13: Quezon | H13: Road Project | I13: Dumagat | J13: Awaiting compliance of Validation and proponent | K13: FPIC completed
A14: 12 | B14: IVA | C14: 44753 | D14: Orophil Stonecraft Inc | E14: EPA-IVA-190 | G14: Quezon | H14: Mining | I14: non-AD | J14: Preparation of FPIC Report | K14: Ongoing review by RRT
A15: 13 | B15: IVA | C15: 44897 | D15: LGU -Tanay Rizal | E15: CP Application for LGSF-Support to Barangay Devt Program of the NTF-ELCAC Proposed projects in Tanay Rizal ( Farm to Market Road Brgy. Daraitan, Tanay and Barangay Health Center in Brgy. Sto. Niño, Tanay, Rizal) | G15: Rizal | H15: Goverment Project-Infrastructure | I15: Dumagat/remontado | J15: Ongoing evaluation of Validation Report by TMSD | K15: FPIC completed
A16: 14 | B16: IVA | C16: 45008 | D16: Sierra View and Leisure Farms | E16: Sierra View Leisure Farm | G16: Tanay | H16: Eco-Tourism | I16: Dumagat/remontado | J16: Ongoing evaluation of FBI report by TMSD | K16: FBI completed | L16: =COUNTIF(K1:K74, "FBI completed") -> 1
A17: 15 | B17: IVA | C17: 2023 | D17: Bluerock Aggregate Corp | E17: AMA-IVA-196 | G17: Rizal | H17: Quarry | I17: Dumagat/Remontado | J17: Refiled application; For payment of FPIC Fee by the proponent | K17: For payment of FPIC Fee
A18: 16 | B18: IVA | C18: 45075 | D18: First Gen Visayas Energy, Inc. | E18: Laguna Wind Power Project | G18: Laguna and Quezon | H18: Energy | I18: Dumagat | J18: The proponent is currently requesting DOE the amendment of Contract Area | K18: Issued CNO | L18: 1
A19: 17 | B19: IVA | C19: 45551 | D19: DSWD FO IV-A | E19: Various Projects for PAMANA IP CDD | G19: General Nakar, Quezon | H19: Goverment Project-Infrastructure | I19: Dumagat/Remontado | J19: Issued Work Order on October 7, 2024 for conduct of validation | K19: For validation | L19: =COUNTIF(K1:K74, "For validation") -> 3
A20: 18 | B20: IVA | C20: 45565 | D20: DPWH Quezon 1st District, Lucban, Quezon | E20: Construction of Multi Purpose Building | G20: Tanauan, Real, Quezon | H20: Goverment Project-Infrastructure | I20: Dumagat/Remontado | J20: Issued Work Order on October 20, 2024 for conduct of validation | K20: For validation
A21: 19 | B21: IVA | C21: 45579 | D21: DOH CHD-IVA | E21: Various Projects for PMNP | G21: Quezon | H21: Goverment Project-Infrastructure | I21: Dumagat/Remontado, Agta, Aeta, Manide, Dumagat | J21: Issued Work Order on December 17, 2024 for conduct of validation | K21: For validation

Sheet REGION 4B
A1: NO | B1: REGION IVB - (PER SERVICE CENTER) | C1: DATE OF FILING OF CP APPLICATION | D1: NAME OF PROPONENT | E1: NAME OF PROJECT | F1: PROJECT COST | G1: LOCATION | H1: Type of Project | I1: AFFECTED AD/ICC/IP (for CP with ongoing FPIC) | J1: STATUS OF APPLICATION | K1: STATUS
A3: 1 | B3: MIMAROPA BROOKES POINT | C3: 42522 | D3: Redmont Consolidated Mines Corporation | E3: Exploration Permit Application (EPA) | G3: Brgy. San Isidra, Malinao and Calategas, Narra; Brgys. Latud and Taburi, Rizal, Bataraza, Palawan | H3: Mining | I3: Tagbanua ICCs | J3: Pala'wan for CEB and Tagbanua for evaluation of ADO and LAO | K3: FPIC completed | L3: =COUNTIF(K1:K227, "FPIC completed") -> 13
A4: =A3+1 -> 2 | B4: MIMAROPA BROOKES POINT | C4: 43353 | D4: Power Source Philippines Inc. Represented by Ramon De Guzman | E4: Microgrid Project | G4: Brgy. Candawaga and Culasian, Rizal, Palawan | H4: Energy | I4: Pala'wan ICCs | J4: For submission of FPIC Book; - for verification from Mam Au | K4: FPIC completed
A5: =A4+1 -> 3 | B5: MIMAROPA BROOKES POINT | C5: 43556 | D5: Mr. Robert Cyrus B. Mayor | E5: Forest Land Use Agreement for Tourism (FLAGt) | G5: Apo. Island, Brgy. Sebaring, Balabac, Palawan | H5: Eco-Tourism | I5: Molbog ICCs | J5: FBI conducted but proponent failed to submit additional requirement. | K5: In active CP application | L5: =COUNTIF(K1:K227, "In active CP application") -> 87
A6: =A5+1 -> 4 | B6: MIMAROPA BROOKES POINT | C6: 43704 | D6: Robert Cyrus Mayor | E6: Recreation Island | G6: Brgy. Sebaring, Bugsok Island, Balabac, Palawan | H6: Eco-Tourism | I6: Molbog ICCs | J6: FBI conducted but proponent failed to submit additional requirement. | K6: In active CP application
A7: =A6+1 -> 5 | B7: MIMAROPA BROOKES POINT | C7: 44004 | D7: Berong Nickel Corporation (BNC) represented by Ms. Deborah A. Arquino, OIC Community Relations | E7: Ship Loading Project | G7: Sitio Little Baguio, Brgy. Maasin, Quezon, Palawan | H7: Others | I7: Pala'wan ICCs | J7: with MOA signing. For CEB delberation. FPIC Book for submission. | K7: FPIC completed
A8: =A7+1 -> 6 | B8: MIMAROPA BROOKES POINT | C8: 44229 | D8: Donna Q. Fuentes | E8: Commercial Sand and Gravel | G8: Brgy. Pangobilian, Brooke's Point, Palawan | H8: Sand and Gravel | I8: Pala'wan ICCs | J8: FBI conducted but proponent failed to submit additional requirement. Dormant Application | K8: In active CP application
A9: =A8+1 -> 7 | B9: MIMAROPA BROOKES POINT | C9: 44279 | D9: DPWH, Region IV-B (MIMAROPA) | E9: Balabac Military Runway | G9: Brgy. Catagupan, Balabac, Palawan | H9: Government | I9: Molbog ICCs | J9: For completion of MOA Negotiation - already operating without MOA . | K9: Ongoing FPIC process | L9: 24
A10: =A9+1 -> 8 | B10: MIMAROPA BROOKES POINT | C10: 44354 | D10: Mr. Roberto R. Del Moro | E10: Commercial Sand And Gravel Permit | G10: Isumbo River, Brgy. Pulot Interior, Sofronio Española, Palawan | H10: Sand and Gravel | I10: Pala'wan ICCs | J10: No follow up from the applicant | K10: In active CP application
A11: =A10+1 -> 9 | B11: MIMAROPA BROOKES POINT | C11: 44461 | D11: Redmont Consolidated Mines Corporation | E11: Proposed Exploration Project | G11: Brgy. San Isidro, Calategas and Malinao, Narra, Brgy. Malatgao and Sumbling, Bataraza and Brgys. Latud and Taburi, Rizal, Palawan | H11: Mining | I11: Pala'wan ICCs | J11: Pala'wan- for CEB and Tagbanua - waiting for the Evaluation of ADO and LAO | K11: FPIC completed
A12: =A11+1 -> 10 | B12: MIMAROPA BROOKES POINT | C12: 44480 | D12: Kalahi CIDSS Pamana IP CDD | E12: Improvement of 1-Unit School Handwashing Facility with Elevated Water Tank/Improvement of Recovery Facility with Construction of 2-Unit Comfort Room/ Construction of 1-Unit of Concrete Footbridge Prepair of Water System | G12: Barangay Malihud, Bataraza, Palawan | H12: Government | I12: Pala'wan ICCs | J12: for Community Validation | K12: For Validation | L12: =COUNTIF(K1:K227, "For Validation") -> 19
A13: =A12+1 -> 11 | B13: MIMAROPA BROOKES POINT | C13: 44708 | D13: Rio Tuba Nickel Mining and Coral Bay Nickel Corporation | E13: Level II Water System into Level III Water System | G13: Brgys. Sandoval, Culandum, Iwahig, Igang-igang, Sarong and Ocayan, Bataraza, Palawan | H13: Water System | I13: Pala'wan ICCs | J13: For MOA Validation | K13: Ongoing FPIC process
A14: =A13+1 -> 12 | B14: MIMAROPA BROOKES POINT | C14: 42860 | D14: Beatriz Acabado | E14: Almaciga Resin Gathering Permit | G14: Barangays Berong and Aramaywan, Quezon, Palawan | H14: Others | I14: Tagbanua ICCs | J14: Memorandum No. 2012-06-352 Series of 2012 - Validation conducted and Report Submitted to Regional Office for Issuance of CP | K14: Validation completed | L14: =COUNTIF(K1:K227, "Validation completed") -> 8
A15: =A14+1 -> 13 | B15: MIMAROPA BROOKES POINT | C15: 42797 | D15: Municipal Government of Sofronio Española | E15: LGU Water Sysytem Project | G15: Pulot Center, Sofronio Española, Palawan | H15: Water System | I15: Pala'wan ICCs | J15: Endorsed by Administrative Officer IV/OIC Delos Santos Last Oct. 20, 2021 for approval of WFP for validation | K15: For Validation
A16: =A15+1 -> 14 | B16: MIMAROPA BROOKES POINT | C16: 43681 | D16: Myrna Mendoza | E16: Forest Land Use Agreement (FLAg) | G16: Sitio Dinamdam, Barangay Panitian, Quezon, Palawan | H16: Others | I16: Pala'wan ICCs | J16: Work Order 2019-09 Series of 2019 - For Issuance of Work Order;For submission of FBI Report to Regional Office; | K16: FBI completed | L16: =COUNTIF(K1:K227, "FBI completed") -> 25
